Workbook

Sheet Expense
A1: Date | B1: Month | C1: Iteams | D1: Expense | E1: Category | F1: Cost Type
A2: 44470 | B2: =TEXT(A2,"mmmm") -> October | C2: Medicine | D2: 2300 | E2: Essential | F2: =IF(D2>2000,"Over Budget","Whitin Budget") -> Over Budget
A3: 44470 | B3: =TEXT(A3,"mmmm") -> October | C3: Online shopping | D3: 767 | E3: Non Essential | F3: =IF(D3>2000,"Over Budget","Whitin Budget") -> Whitin Budget
A4: 44470 | B4: =TEXT(A4,"mmmm") -> October | C4: Other essential items | D4: 2500 | E4: Essential | F4: =IF(D4>2000,"Over Budget","Whitin Budget") -> Over Budget
A5: 44473 | B5: =TEXT(A5,"mmmm") -> October | C5: Vegetables & Fruit | D5: 710 | E5: Essential | F5: =IF(D5>2000,"Over Budget","Whitin Budget") -> Whitin Budget
A6: 44473 | B6: =TEXT(A6,"mmmm") -> October | C6: Fish & Chicken | D6: 760 | E6: Non-Essential | F6: =IF(D6>2000,"Over Budget","Whitin Budget") -> Whitin Budget
A7: 44476 | B7: =TEXT(A7,"mmmm") -> October | C7: Gifts | D7: 1900 | E7: Non-Essential | F7: =IF(D7>2000,"Over Budget","Whitin Budget") -> Whitin Budget
A8: 44477 | B8: =TEXT(A8,"mmmm") -> October | C8: Ordering food | D8: 450 | E8: Essential | F8: =IF(D8>2000,"Over Budget","Whitin Budget") -> Whitin Budget
A9: 44484 | B9: =TEXT(A9,"mmmm") -> October | C9: Movie with friends | D9: 620 | E9: Non-Essential | F9: =IF(D9>2000,"Over Budget","Whitin Budget") -> Whitin Budget
A10: 44485 | B10: =TEXT(A10,"mmmm") -> October | C10: Mobile Bill Payment | D10: 470 | E10: Essential | F10: =IF(D10>2000,"Over Budget","Whitin Budget") -> Whitin Budget
A11: 44487 | B11: =TEXT(A11,"mmmm") -> October | C11: Online shopping | D11: 970 | E11: Non-Essential | F11: =IF(D11>2000,"Over Budget","Whitin Budget") -> Whitin Budget
A12: 44487 | B12: =TEXT(A12,"mmmm") -> October | C12: Medicine | D12: 1075 | E12: Essential | F12: =IF(D12>2000,"Over Budget","Whitin Budget") -> Whitin Budget
A13: 44488 | B13: =TEXT(A13,"mmmm") -> October | C13: Ordering food | D13: 489 | E13: Non-Essential | F13: =IF(D13>2000,"Over Budget","Whitin Budget") -> Whitin Budget
... A51: 44553 | B51: =TEXT(A51,"mmmm") -> December | C51: Vegetables & Fruit | D51: 450 | E51: Essential | F51: =IF(D51>2000,"Over Budget","Whitin Budget") -> Whitin Budget
D52: =SUM(D2:D51) -> 57045.27

Sheet Tasks
B1: Task to Perform
B2: How many times has Priya done transactions on online shopping, ordering food and gifts?
B3: Calculate the total expenses against each distinct item.
B4: Arrange the item-wise total expense in descending order.
B5: Present the item-wise total expense through a chart that shows the expense of each item as a percentage of the total expense. Don’t take trip expenses into consideration. | C5: create a table to show item wise total expense
B6: Present the expense pattern visually over 3 months.
B7: Add a new column to the data table, name it as “Category” and apply data validation with drop-down fields as “Essentials” and “Non-essentials”. Fill in the column.
B8: Add another new column and name it as “Cost Type”. For each item, if the expense is more than 2000, tag it as “Over budget”, else, tag it as “Within budget”.
B9: Mention the ways how Priya can reduce her expenses. Justify each point.

Sheet Sheet1
A1: Q1. How many times has Priya done transactions on online shopping, ordering food and gifts?
E3: Online shopping: | F3: =COUNTIF(Expense!C:C,"Online Shopping") -> 6
E4: Ordering food: | F4: =COUNTIF(Expense!C:C,"Ordering food") -> 5
E5: Gifts : | F5: =COUNTIF(Expense!C:C,"Gifts") -> 4
E6: Total | F6: =SUM(F3:F5) -> 15
E9: Q2. Calculate the total expenses against each distinct item.
E11: Items | F11: Total Expense
E12: Medicine | F12: =SUMIF(Expense!C:C,Sheet1!E12,Expense!D:D) -> 7775
E13: Online shopping | F13: =SUMIF(Expense!C:C,Sheet1!E13,Expense!D:D) -> 7464
E14: Other essential items | F14: =SUMIF(Expense!C:C,Sheet1!E14,Expense!D:D) -> 10194.1
E15: Vegetables & Fruit | F15: =SUMIF(Expense!C:C,Sheet1!E15,Expense!D:D) -> 3217
E16: Fish & Chicken | F16: =SUMIF(Expense!C:C,Sheet1!E16,Expense!D:D) -> 3342
E17: Gifts | F17: =SUMIF(Expense!C:C,Sheet1!E17,Expense!D:D) -> 5688
E18: Ordering food | F18: =SUMIF(Expense!C:C,Sheet1!E18,Expense!D:D) -> 1857
E19: Movie with friends | F19: =SUMIF(Expense!C:C,Sheet1!E19,Expense!D:D) -> 2586
E20: Mobile Bill Payment | F20: =SUMIF(Expense!C:C,Sheet1!E20,Expense!D:D) -> 1411.26
E21: Cab to office | F21: =SUMIF(Expense!C:C,Sheet1!E21,Expense!D:D) -> 1510.91
E22: Trip | F22: =SUMIF(Expense!C:C,Sheet1!E22,Expense!D:D) -> 12000
E25: Q3-Arrange the item-wise total expense in descending order.
E27: Iteams | F27: Total Expense
E28: Vegetables & Fruit | F28: =SUMIF(Expense!C:C,Sheet1!E31,Expense!D:D) -> 1857
E29: Trip | F29: =SUMIF(Expense!C:C,Sheet1!E38,Expense!D:D) -> 1510.91
E30: Other essential items | F30: =SUMIF(Expense!C:C,Sheet1!E30,Expense!D:D) -> 10194.1
E31: Ordering food | F31: =SUMIF(Expense!C:C,Sheet1!E34,Expense!D:D) -> 1411.26
E32: Online shopping | F32: =SUMIF(Expense!C:C,Sheet1!E29,Expense!D:D) -> 12000
E33: Movie with friends | F33: =SUMIF(Expense!C:C,Sheet1!E35,Expense!D:D) -> 7775
E34: Mobile Bill Payment | F34: 5688
E35: Medicine | F35: =SUMIF(Expense!C:C,Sheet1!E28,Expense!D:D) -> 3217
E36: Gifts | F36: =SUMIF(Expense!C:C,Sheet1!E33,Expense!D:D) -> 2586
E37: Fish & Chicken | F37: =SUMIF(Expense!C:C,Sheet1!E32,Expense!D:D) -> 7464
E38: Cab to office | F38: =SUMIF(Expense!C:C,Sheet1!E37,Expense!D:D) -> 3342
E39: Total Expense | F39: =SUM(F28:F38) -> 57045.27
E41: Q4-Present the item-wise total expense through a chart that shows the expense of each item as a percentage of the total expense. Don’t take trip expenses into consideration.
E43: Iteams | F43: Total Expense | H43: Percentage
E44: Vegetables & Fruit | F44: =SUMIF(Expense!C:C,Sheet1!E47,Expense!D:D) -> 1857 | H44: =F44/F55 -> 0.032553093
E45: Trip | F45: =SUMIF(Expense!C:C,Sheet1!E54,Expense!D:D) -> 1510.91 | H45: =F45/F55 -> 0.026486157
E46: Other essential items | F46: =SUMIF(Expense!C:C,Sheet1!E46,Expense!D:D) -> 10194.1 | H46: =F46/F55 -> 0.17870193
E47: Ordering food | F47: =SUMIF(Expense!C:C,Sheet1!E50,Expense!D:D) -> 1411.26 | H47: =F47/F55 -> 0.024739299
E48: Online shopping | F48: =SUMIF(Expense!C:C,Sheet1!E45,Expense!D:D) -> 12000 | H48: =F48/F55 -> 0.21035925
E49: Movie with friends | F49: =SUMIF(Expense!C:C,Sheet1!E51,Expense!D:D) -> 7775 | H49: =F49/F55 -> 0.13629526
...
